[2022-06-12 17:10:41,836] {taskinstance.py:1032} INFO - Dependencies all met for <TaskInstance: CSV_TO_DS.create_schema_and_tables_ds scheduled__2022-06-11T17:10:29.833042+00:00 [queued]>
[2022-06-12 17:10:41,847] {taskinstance.py:1032} INFO - Dependencies all met for <TaskInstance: CSV_TO_DS.create_schema_and_tables_ds scheduled__2022-06-11T17:10:29.833042+00:00 [queued]>
[2022-06-12 17:10:41,847] {taskinstance.py:1238} INFO - 
--------------------------------------------------------------------------------
[2022-06-12 17:10:41,847] {taskinstance.py:1239} INFO - Starting attempt 1 of 2
[2022-06-12 17:10:41,847] {taskinstance.py:1240} INFO - 
--------------------------------------------------------------------------------
[2022-06-12 17:10:41,863] {taskinstance.py:1259} INFO - Executing <Task(PostgresOperator): create_schema_and_tables_ds> on 2022-06-11 17:10:29.833042+00:00
[2022-06-12 17:10:41,868] {standard_task_runner.py:52} INFO - Started process 4631 to run task
[2022-06-12 17:10:41,870] {standard_task_runner.py:76} INFO - Running: ['***', 'tasks', 'run', 'CSV_TO_DS', 'create_schema_and_tables_ds', 'scheduled__2022-06-11T17:10:29.833042+00:00', '--job-id', '3', '--raw', '--subdir', 'DAGS_FOLDER/csv_to_ds.py', '--cfg-path', '/tmp/tmplm22ts7u', '--error-file', '/tmp/tmpwg4vlr84']
[2022-06-12 17:10:41,871] {standard_task_runner.py:77} INFO - Job 3: Subtask create_schema_and_tables_ds
[2022-06-12 17:10:41,939] {logging_mixin.py:109} INFO - Running <TaskInstance: CSV_TO_DS.create_schema_and_tables_ds scheduled__2022-06-11T17:10:29.833042+00:00 [running]> on host 85bfea1e024d
[2022-06-12 17:10:41,990] {taskinstance.py:1426} INFO - Exporting the following env vars:
AIRFLOW_CTX_DAG_OWNER=***
AIRFLOW_CTX_DAG_ID=CSV_TO_DS
AIRFLOW_CTX_TASK_ID=create_schema_and_tables_ds
AIRFLOW_CTX_EXECUTION_DATE=2022-06-11T17:10:29.833042+00:00
AIRFLOW_CTX_DAG_RUN_ID=scheduled__2022-06-11T17:10:29.833042+00:00
[2022-06-12 17:10:41,999] {base.py:79} INFO - Using connection to: id: postgres. Host: 127.0.0.1, Port: None, Schema: postgres, Login: ***, Password: ***, extra: {}
[2022-06-12 17:10:42,000] {taskinstance.py:1700} ERROR - Task failed with exception
Traceback (most recent call last):
  File "/home/airflow/.local/lib/python3.7/site-packages/airflow/models/taskinstance.py", line 1329, in _run_raw_task
    self._execute_task_with_callbacks(context)
  File "/home/airflow/.local/lib/python3.7/site-packages/airflow/models/taskinstance.py", line 1455, in _execute_task_with_callbacks
    result = self._execute_task(context, self.task)
  File "/home/airflow/.local/lib/python3.7/site-packages/airflow/models/taskinstance.py", line 1511, in _execute_task
    result = execute_callable(context=context)
  File "/home/airflow/.local/lib/python3.7/site-packages/airflow/providers/postgres/operators/postgres.py", line 69, in execute
    self.hook.run(self.sql, self.autocommit, parameters=self.parameters)
  File "/home/airflow/.local/lib/python3.7/site-packages/airflow/hooks/dbapi.py", line 198, in run
    with closing(self.get_conn()) as conn:
  File "/home/airflow/.local/lib/python3.7/site-packages/airflow/providers/postgres/hooks/postgres.py", line 115, in get_conn
    self.conn = psycopg2.connect(**conn_args)
  File "/home/airflow/.local/lib/python3.7/site-packages/psycopg2/__init__.py", line 122, in connect
    conn = _connect(dsn, connection_factory=connection_factory, **kwasync)
psycopg2.OperationalError: connection to server at "127.0.0.1", port 5432 failed: Connection refused
	Is the server running on that host and accepting TCP/IP connections?

[2022-06-12 17:10:42,012] {taskinstance.py:1277} INFO - Marking task as UP_FOR_RETRY. dag_id=CSV_TO_DS, task_id=create_schema_and_tables_ds, execution_date=20220611T171029, start_date=20220612T171041, end_date=20220612T171042
[2022-06-12 17:10:42,023] {standard_task_runner.py:92} ERROR - Failed to execute job 3 for task create_schema_and_tables_ds
Traceback (most recent call last):
  File "/home/airflow/.local/lib/python3.7/site-packages/airflow/task/task_runner/standard_task_runner.py", line 85, in _start_by_fork
    args.func(args, dag=self.dag)
  File "/home/airflow/.local/lib/python3.7/site-packages/airflow/cli/cli_parser.py", line 48, in command
    return func(*args, **kwargs)
  File "/home/airflow/.local/lib/python3.7/site-packages/airflow/utils/cli.py", line 92, in wrapper
    return f(*args, **kwargs)
  File "/home/airflow/.local/lib/python3.7/site-packages/airflow/cli/commands/task_command.py", line 298, in task_run
    _run_task_by_selected_method(args, dag, ti)
  File "/home/airflow/.local/lib/python3.7/site-packages/airflow/cli/commands/task_command.py", line 107, in _run_task_by_selected_method
    _run_raw_task(args, ti)
  File "/home/airflow/.local/lib/python3.7/site-packages/airflow/cli/commands/task_command.py", line 184, in _run_raw_task
    error_file=args.error_file,
  File "/home/airflow/.local/lib/python3.7/site-packages/airflow/utils/session.py", line 70, in wrapper
    return func(*args, session=session, **kwargs)
  File "/home/airflow/.local/lib/python3.7/site-packages/airflow/models/taskinstance.py", line 1329, in _run_raw_task
    self._execute_task_with_callbacks(context)
  File "/home/airflow/.local/lib/python3.7/site-packages/airflow/models/taskinstance.py", line 1455, in _execute_task_with_callbacks
    result = self._execute_task(context, self.task)
  File "/home/airflow/.local/lib/python3.7/site-packages/airflow/models/taskinstance.py", line 1511, in _execute_task
    result = execute_callable(context=context)
  File "/home/airflow/.local/lib/python3.7/site-packages/airflow/providers/postgres/operators/postgres.py", line 69, in execute
    self.hook.run(self.sql, self.autocommit, parameters=self.parameters)
  File "/home/airflow/.local/lib/python3.7/site-packages/airflow/hooks/dbapi.py", line 198, in run
    with closing(self.get_conn()) as conn:
  File "/home/airflow/.local/lib/python3.7/site-packages/airflow/providers/postgres/hooks/postgres.py", line 115, in get_conn
    self.conn = psycopg2.connect(**conn_args)
  File "/home/airflow/.local/lib/python3.7/site-packages/psycopg2/__init__.py", line 122, in connect
    conn = _connect(dsn, connection_factory=connection_factory, **kwasync)
psycopg2.OperationalError: connection to server at "127.0.0.1", port 5432 failed: Connection refused
	Is the server running on that host and accepting TCP/IP connections?

[2022-06-12 17:10:42,047] {local_task_job.py:154} INFO - Task exited with return code 1
[2022-06-12 17:10:42,110] {local_task_job.py:264} INFO - 0 downstream tasks scheduled from follow-on schedule check
