[2022-06-08 11:22:14,155] {taskinstance.py:1159} INFO - Dependencies all met for <TaskInstance: CSV_TO_DS.SEND_DS_ft_balance_f manual__2022-06-08T11:17:04.937770+00:00 [queued]>
[2022-06-08 11:22:14,163] {taskinstance.py:1159} INFO - Dependencies all met for <TaskInstance: CSV_TO_DS.SEND_DS_ft_balance_f manual__2022-06-08T11:17:04.937770+00:00 [queued]>
[2022-06-08 11:22:14,163] {taskinstance.py:1356} INFO - 
--------------------------------------------------------------------------------
[2022-06-08 11:22:14,163] {taskinstance.py:1357} INFO - Starting attempt 2 of 2
[2022-06-08 11:22:14,163] {taskinstance.py:1358} INFO - 
--------------------------------------------------------------------------------
[2022-06-08 11:22:14,175] {taskinstance.py:1377} INFO - Executing <Task(PythonOperator): SEND_DS_ft_balance_f> on 2022-06-08 11:17:04.937770+00:00
[2022-06-08 11:22:14,179] {standard_task_runner.py:52} INFO - Started process 6497 to run task
[2022-06-08 11:22:14,182] {standard_task_runner.py:79} INFO - Running: ['***', 'tasks', 'run', 'CSV_TO_DS', 'SEND_DS_ft_balance_f', 'manual__2022-06-08T11:17:04.937770+00:00', '--job-id', '145', '--raw', '--subdir', 'DAGS_FOLDER/csv_to_ds.py', '--cfg-path', '/tmp/tmp_s5k0ax6', '--error-file', '/tmp/tmppqegpk7m']
[2022-06-08 11:22:14,183] {standard_task_runner.py:80} INFO - Job 145: Subtask SEND_DS_ft_balance_f
[2022-06-08 11:22:14,233] {task_command.py:370} INFO - Running <TaskInstance: CSV_TO_DS.SEND_DS_ft_balance_f manual__2022-06-08T11:17:04.937770+00:00 [running]> on host 33a1fdf44d41
[2022-06-08 11:22:14,310] {taskinstance.py:1571} INFO - Exporting the following env vars:
AIRFLOW_CTX_DAG_OWNER=***
AIRFLOW_CTX_DAG_ID=CSV_TO_DS
AIRFLOW_CTX_TASK_ID=SEND_DS_ft_balance_f
AIRFLOW_CTX_EXECUTION_DATE=2022-06-08T11:17:04.937770+00:00
AIRFLOW_CTX_TRY_NUMBER=2
AIRFLOW_CTX_DAG_RUN_ID=manual__2022-06-08T11:17:04.937770+00:00
[2022-06-08 11:22:14,319] {base.py:68} INFO - Using connection ID 'postgres' for task execution.
[2022-06-08 11:22:14,328] {csv_to_ds.py:83} INFO - Column on_date changed date-time format
[2022-06-08 11:22:14,328] {csv_to_ds.py:90} INFO - Table ft_balance_f read in pandas success.
[2022-06-08 11:22:14,336] {csv_to_ds.py:91} INFO - 
      on_date  account_rk  currency_rk  balance_out
0 2017-12-31    36237725           35     38318.13
1 2017-12-31       24656           35     80533.62
2 2017-12-31    18849846           34     63891.96
3 2017-12-31     1972647           34     87732.10
4 2017-12-31    34157174           34     97806.90
[2022-06-08 11:22:14,349] {csv_to_ds.py:103} INFO - (psycopg2.errors.UniqueViolation) duplicate key value violates unique constraint "ft_balance_f_pkey"
DETAIL:  Key (on_date, account_rk)=(2017-12-31, 36237725) already exists.

[SQL: INSERT INTO ds.ft_balance_f (on_date, account_rk, currency_rk, balance_out) VALUES (%(on_date)s, %(account_rk)s, %(currency_rk)s, %(balance_out)s)]
[parameters: ({'on_date': datetime.datetime(2017, 12, 31, 0, 0), 'account_rk': 36237725, 'currency_rk': 35, 'balance_out': 38318.13}, {'on_date': datetime.datetime(2017, 12, 31, 0, 0), 'account_rk': 24656, 'currency_rk': 35, 'balance_out': 80533.62}, {'on_date': datetime.datetime(2017, 12, 31, 0, 0), 'account_rk': 18849846, 'currency_rk': 34, 'balance_out': 63891.96}, {'on_date': datetime.datetime(2017, 12, 31, 0, 0), 'account_rk': 1972647, 'currency_rk': 34, 'balance_out': 87732.1}, {'on_date': datetime.datetime(2017, 12, 31, 0, 0), 'account_rk': 34157174, 'currency_rk': 34, 'balance_out': 97806.9}, {'on_date': datetime.datetime(2017, 12, 31, 0, 0), 'account_rk': 48829156, 'currency_rk': 34, 'balance_out': 87620.47}, {'on_date': datetime.datetime(2017, 12, 31, 0, 0), 'account_rk': 13905, 'currency_rk': 34, 'balance_out': 29554.0}, {'on_date': datetime.datetime(2017, 12, 31, 0, 0), 'account_rk': 17244, 'currency_rk': 34, 'balance_out': 25852.49}  ... displaying 10 of 112 total bound parameter sets ...  {'on_date': datetime.datetime(2017, 12, 31, 0, 0), 'account_rk': 18007, 'currency_rk': 34, 'balance_out': 58966.57}, {'on_date': datetime.datetime(2017, 12, 31, 0, 0), 'account_rk': 44195, 'currency_rk': 44, 'balance_out': 3818.77})]
(Background on this error at: http://sqlalche.me/e/14/gkpj)
[2022-06-08 11:22:19,350] {taskinstance.py:1889} ERROR - Task failed with exception
Traceback (most recent call last):
  File "/home/airflow/.local/lib/python3.7/site-packages/airflow/operators/python.py", line 171, in execute
    return_value = self.execute_callable()
  File "/home/airflow/.local/lib/python3.7/site-packages/airflow/operators/python.py", line 189, in execute_callable
    return self.python_callable(*self.op_args, **self.op_kwargs)
  File "/opt/airflow/dags/csv_to_ds.py", line 113, in send_csv_to_ds
    ins = LogsLoadCsvToDs.insert().values(
AttributeError: type object 'LogsLoadCsvToDs' has no attribute 'insert'
[2022-06-08 11:22:19,358] {taskinstance.py:1400} INFO - Marking task as FAILED. dag_id=CSV_TO_DS, task_id=SEND_DS_ft_balance_f, execution_date=20220608T111704, start_date=20220608T112214, end_date=20220608T112219
[2022-06-08 11:22:19,368] {standard_task_runner.py:97} ERROR - Failed to execute job 145 for task SEND_DS_ft_balance_f (type object 'LogsLoadCsvToDs' has no attribute 'insert'; 6497)
[2022-06-08 11:22:19,383] {local_task_job.py:156} INFO - Task exited with return code 1
[2022-06-08 11:22:19,412] {local_task_job.py:273} INFO - 0 downstream tasks scheduled from follow-on schedule check
